{
 "cells": [
  {
   "cell_type": "code",
   "execution_count": null,
   "id": "6a30a028-bf21-4286-9197-ad1f0708fa13",
   "metadata": {},
   "outputs": [],
   "source": [
    "1: we use the \"Exception\" class as the base class for custom exceptions in python\n",
    "to inherit built-in functionality and ensure consistency with the standard\n",
    "exception hierarchy...\n",
    "\n",
    "Example:\n",
    "class CustomException(Exception):\n",
    "    pass\n",
    "\n",
    "In this example i defined a custom exception called 'customexception'.\n",
    "it inherits from the exception class. the pass statement indicates tht we are not\n",
    "addding any additional functionality to exception but simply inheriting from \n",
    "the exception class\n",
    "  In Python exception class is the base class for all buit in exception such as\n",
    "    'valueError','typeError' and so on...\n",
    " "
   ]
  },
  {
   "cell_type": "code",
   "execution_count": null,
   "id": "d767b097-7c0f-46fa-a8a9-56bfb502d48a",
   "metadata": {},
   "outputs": [],
   "source": []
  },
  {
   "cell_type": "code",
   "execution_count": null,
   "id": "47d260cc-4887-4247-9857-18500185b28a",
   "metadata": {},
   "outputs": [],
   "source": [
    "2: An example that prints the python exception hierarchy using\n",
    "   'logging' module:\n",
    "\n",
    "import logging\n",
    "\n",
    "# Configure logging\n",
    "logging.basicConfig(filename='example.log', level=logging.DEBUG)\n",
    "\n",
    "try:\n",
    "    num1 = int(input(\"Enter a number: \"))\n",
    "    num2 = int(input(\"Enter another number: \"))\n",
    "    result = num1 / num2\n",
    "    print(\"The result is:\", result)\n",
    "except ValueError:\n",
    "    logging.error(\"Invalid input\")\n",
    "except ZeroDivisionError:\n",
    "    logging.error(\"Cannot divide by zero\")\n",
    "\n",
    ">first import the logging module to enable logging.\n",
    ">then,configure logging to write to a file named example.log and \n",
    " set the logging level to DEBUG.\n",
    "> I use a try block to enclose the code that may raise exceptions.\n",
    "> I prompt the user to enter two integers num1 and num2.\n",
    "> then i  attempt to perform division operation on num1 and num2 and store\n",
    "  the result in result.\n",
    "> print the result if the division was successful.\n",
    "> the i use except statements to catch specific exceptions that may occur in\n",
    "  the try block.\n",
    "> If a 'ValueError' occurs, we log an error message indicating that the\n",
    "  input was invalid.\n",
    "> if  'ZeroDivisionError' occurs, we log an error message indicating that we cannot divide by zero.\n",
    "\n",
    "      \n",
    "    \n",
    "    "
   ]
  },
  {
   "cell_type": "code",
   "execution_count": null,
   "id": "b9c9e5be-0d11-42a2-9125-078619eba63a",
   "metadata": {},
   "outputs": [],
   "source": []
  },
  {
   "cell_type": "code",
   "execution_count": null,
   "id": "51f18685-8f63-46bf-82dc-b007a850bfd1",
   "metadata": {},
   "outputs": [],
   "source": [
    "3: The 'ArithmeticError' class is a built-in exception class in Python that\n",
    "   is raised for arithmetic errors, such as division by zero or overflow.\n",
    "    \n",
    "Here are two common errors defined in the ArithmeticError class\n",
    "\n",
    "1.\"ZeroDivisionError\"\n",
    "This error is raised when you attempt to divide by zero.\n",
    "Example:\n",
    " \n",
    "a = 10\n",
    "b = 0\n",
    "try:\n",
    "    result = a / b\n",
    "except ZeroDivisionError as e:\n",
    "    print(\" ZeroDivisionError:\", e)\n",
    "    \n",
    "\n",
    "In this example, I have define two variables a and b, where b is zero.\n",
    "When we attempt to divide a by b, a ZeroDivisionError is raised. \n",
    "We catch the error in the except block and print the error message.\n",
    "\n",
    "\n",
    "2. \"OverflowError\"\n",
    "\n",
    "This error is raised when a calculation exceeds the maximum representable\n",
    "value for a numeric type.\n",
    "\n",
    "Example:\n",
    "\n",
    "import sys\n",
    "\n",
    "try:\n",
    "    result = sys.maxsize * 2\n",
    "    print(result)\n",
    "except OverflowError:\n",
    "    print(\"OverflowError: Result too large to represent as an integer\")\n",
    "\n",
    "    \n",
    "In this example, Iam trying to calculate the result of multiplying the\n",
    "maximum value representable as an integer by 2. This calculation results in\n",
    "a number that is too large to represent as an integer, which raises an \n",
    "\"OverflowError\". We catch this error using a try-except block and print a\n",
    "message to indicate the error.\n",
    "\n",
    "\n",
    "\n"
   ]
  },
  {
   "cell_type": "code",
   "execution_count": null,
   "id": "7ac9281d-fd67-4a5d-9eb9-114b82040088",
   "metadata": {},
   "outputs": [],
   "source": []
  },
  {
   "cell_type": "code",
   "execution_count": null,
   "id": "e46878bb-a197-43d1-bcae-867bdbff2824",
   "metadata": {},
   "outputs": [],
   "source": [
    "4: The LookupError class is used as the base class for exception raised when\n",
    "an index or key used to access a sequence or dictionary is invalid.\n",
    " It is a subclass of the Exception class and is further subclassed into\n",
    "specific lookup-related exceptions such as IndexError and KeyError.\n",
    "\n",
    "# IndexError example\n",
    "my_list = [1, 2, 3]\n",
    "try:\n",
    "    value = my_list[3]  # index 3 is out of range\n",
    "except IndexError:\n",
    "    print(\"Error: Index out of range\")\n",
    "\n",
    "In this example, we have a list with three elements, but i try to access\n",
    "the element at index 3, which is out of range. This raises an \"IndexError\", \n",
    "which i catch using a try-except block and print an error message.\n",
    "\n",
    "\n",
    "# KeyError example\n",
    "my_dict = {'a': 1, 'b': 2, 'c': 3}\n",
    "try:\n",
    "    value = my_dict['d']  # key 'd' does not exist\n",
    "except KeyError:\n",
    "    print(\"Error: Key not found\")\n",
    "\n",
    "\n",
    "In this example, we have a dictionary with keys 'a', 'b', and 'c'. i have\n",
    "try to access the value associated with the key 'd', which does not exist in\n",
    "the dictionary. This raises a \"KeyError\", which we catch using a try-except\n",
    "block and print an error message.\n",
    "\n"
   ]
  },
  {
   "cell_type": "code",
   "execution_count": null,
   "id": "9bcd90ba-c164-4804-82d2-4978aabbeca9",
   "metadata": {},
   "outputs": [],
   "source": []
  },
  {
   "cell_type": "code",
   "execution_count": null,
   "id": "78d46d42-8ac9-43fc-9bf7-69bdf6e34d9f",
   "metadata": {},
   "outputs": [],
   "source": [
    "5:\"import Error\"  is a built-in Python exception that is raised when a \n",
    "module or package cannot be imported for any reason.\n",
    "\n",
    "This can happen if the module or package does not exist, or if there is an\n",
    "error in the code within the module or package. ImportError is a catch-all\n",
    "exception that can be used to handle import-related errors in a generalized\n",
    "way. By catching and handling 'ImportError' exceptions, you can provide more\n",
    "meaningful error messages to users or take appropriate actions to resolve the error.\n",
    "\n",
    "\"ModuleNotFoundError\"\n",
    "it is a subclass of the ImportError exception that is raised when a module\n",
    "or package cannot be found by the Python interpreter. This usually occurs \n",
    "when you try to import a module that doesnt exist or has not been installed\n",
    "yet. The ModuleNotFoundError exception was introduced in Python 3.6 as a\n",
    "more specific error message for missing modules, making it easier to \n",
    "diagnose and fix import-related issues. When catching this exception, you \n",
    "can provide a more targeted error message to users or take appropriate\n",
    "actions to resolve the error.\n",
    "\n",
    "\n"
   ]
  },
  {
   "cell_type": "code",
   "execution_count": null,
   "id": "9a6a9106-304e-4246-b3ea-018e37523ec4",
   "metadata": {},
   "outputs": [],
   "source": []
  },
  {
   "cell_type": "code",
   "execution_count": null,
   "id": "ee4e20ce-2a69-4b84-839f-a46230ed6172",
   "metadata": {},
   "outputs": [],
   "source": [
    "6:Here are some best practices for exception handling in Python:\n",
    "\n",
    "1.Catch specific exceptions.\n",
    "2.Keep exception handlers short.\n",
    "3.Use the finally block.\n",
    "4.Log errors.\n",
    "5.Use descriptive error messages.\n",
    "6.Use with statement when working with external resources.\n",
    "7.Dont use exceptions for flow control.\n",
    "8.Reraise exceptions when necessary.\n",
    "\n",
    "\n"
   ]
  }
 ],
 "metadata": {
  "kernelspec": {
   "display_name": "Python 3 (ipykernel)",
   "language": "python",
   "name": "python3"
  },
  "language_info": {
   "codemirror_mode": {
    "name": "ipython",
    "version": 3
   },
   "file_extension": ".py",
   "mimetype": "text/x-python",
   "name": "python",
   "nbconvert_exporter": "python",
   "pygments_lexer": "ipython3",
   "version": "3.10.8"
  }
 },
 "nbformat": 4,
 "nbformat_minor": 5
}
